Workbook
Name _COM01: #REF!
Name _COM02: #REF!
Name _COM03: #REF!
Name _COM04: #REF!
Name _COM05: #REF!
Name _COM06: #REF!
Name _COM07: #REF!
Name _COM08: #REF!
Name _COM09: #REF!
Name _COM10: #REF!
Name _COM11: #REF!
Name _COM12: #REF!
Name \0: #REF!
Name AGREG: #REF!
Name BLANCO: #REF!
Name COM00: #REF!
Name COM04B: #REF!
Name COM08B: #REF!
Name COM12B: #REF!
Name COMOBS: #REF!
Name CORRE1: #REF!
Name CORRE12: #REF!
Name CORRE13: #REF!
Name CORRE14: #REF!
Name CORRE15: #REF!
Name CORRE2: #REF!
Name CORRE3: #REF!
Name CORRE4: #REF!
Name CORRE5: #REF!
Name CORRE6: #REF!
Name CORRE7: #REF!
Name CRIDES: #REF!
Name CRIHAS: #REF!
Name CRILIMP: #REF!
Name CRILIMP2: #REF!
Name FERIA: #REF!
Name FIN: #REF!
Name FORDESPLDIA: #REF!
Name FORMULA1: #REF!
Name FORMULA2: #REF!
Name FORMULA3: #REF!
Name IND: #REF!
Name INDDES: #REF!
Name INDHAS: #REF!
Name INI: #REF!
Name LIMP: #REF!
Name PON_FEC_TOT: #REF!
Name PON_RAN1_PRIV: #REF!
Name PON_RAN1_PUB: #REF!
Name PON_RAN1_TOT: #REF!
Name PON_REP: #REF!
Name PUB_DAT_PRI_EXT: #REF!
Name PUB_DAT_PRI_NAC: #REF!
Name PUB_DAT_PUB_EXT: #REF!
Name PUB_DAT_PUB_NAC: #REF!
Name PUB_DAT_TOT_EXT: #REF!
Name PUB_DAT_TOT_NAC: #REF!
Name PUB_FEC_EXT: #REF!
Name PUB_FEC_NAC: #REF!
Name PUB_REP: #REF!

Sheet 4 GRANOS
A2: Pesos VBP 2026 | C2: 0.62170936 | D2: 0.14775265 | E2: 0.17421534 | F2: =1-C2-D2-E2 -> 0.056322652
C3: SOJA | D3: TRIGO | E3: MAIZ | F3: GIRASOL
A4: 33970 | B4: E-93 | C4: =SOJA!K2 -> 221.58835 | D4: =TRIGO!K2 -> 130.91755 | E4: =MAIZ!K2 -> 122.60533 | F4: =GIRASOL!K2 -> 210.55907 | K4: =+C4*C$2+D4*D$2+E4*E$2+F4*F$2 -> 190.32594 | L4: =+AVERAGE(K4:K111) -> 178.61766 | M4: =+AVERAGE(K112:K279) -> 266.24122 | N4: E-93
A5: 34001 | B5: F | C5: =SOJA!K3 -> 204.14005 | D5: =TRIGO!K3 -> 132.08606 | E5: =MAIZ!K3 -> 97.000704 | F5: =GIRASOL!K3 -> 210.11488 | K5: =+C5*C$2+D5*D$2+E5*E$2+F5*F$2 -> 175.16508 | L5: =+L4 -> 178.61766 | M5: =+M4 -> 266.24122 | N5: F
A6: 34029 | B6: M | C6: =SOJA!K4 -> 201.73565 | D6: =TRIGO!K4 -> 126.04635 | E6: =MAIZ!K4 -> 86.080435 | F6: =GIRASOL!K4 -> 207.66905 | K6: =+C6*C$2+D6*D$2+E6*E$2+F6*F$2 -> 170.73763 | L6: =+L5 -> 178.61766 | M6: =+M5 -> 266.24122 | N6: M
A7: 34060 | B7: A | C7: =SOJA!K5 -> 203.45604 | D7: =TRIGO!K5 -> 128.73115 | E7: =MAIZ!K5 -> 92.240433 | F7: =GIRASOL!K5 -> 220.08466 | K7: =+C7*C$2+D7*D$2+E7*E$2+F7*F$2 -> 173.97634 | L7: =+L6 -> 178.61766 | M7: =+M6 -> 266.24122 | N7: A
A8: 34090 | B8: M | C8: =SOJA!K6 -> 205.74875 | D8: =TRIGO!K6 -> 133.13184 | E8: =MAIZ!K6 -> 96.095161 | F8: =GIRASOL!K6 -> 236.65936 | K8: =+C8*C$2+D8*D$2+E8*E$2+F8*F$2 -> 177.65704 | L8: =+L7 -> 178.61766 | M8: =+M7 -> 266.24122 | N8: M
A9: 34121 | B9: J | C9: =SOJA!K7 -> 209.05177 | D9: =TRIGO!K7 -> 136.14152 | E9: =MAIZ!K7 -> 96.392174 | F9: =GIRASOL!K7 -> 237.82036 | K9: =+C9*C$2+D9*D$2+E9*E$2+F9*F$2 -> 180.27238 | L9: =+L8 -> 178.61766 | M9: =+M8 -> 266.24122 | N9: J
A10: 34151 | B10: J | C10: =SOJA!K8 -> 241.74958 | D10: =TRIGO!K8 -> 135.65583 | E10: =MAIZ!K8 -> 105.95017 | F10: =GIRASOL!K8 -> 243.66064 | K10: =+C10*C$2+D10*D$2+E10*E$2+F10*F$2 -> 202.52324 | L10: =+L9 -> 178.61766 | M10: =+M9 -> 266.24122 | N10: J
A11: 34182 | B11: A | C11: =SOJA!K9 -> 238.18726 | D11: =TRIGO!K9 -> 134.81269 | E11: =MAIZ!K9 -> 121.92619 | F11: =GIRASOL!K9 -> 239.14384 | K11: =+C11*C$2+D11*D$2+E11*E$2+F11*F$2 -> 202.71281 | L11: =+L10 -> 178.61766 | M11: =+M10 -> 266.24122 | N11: A
A12: 34213 | B12: S | C12: =SOJA!K10 -> 227.89159 | D12: =TRIGO!K10 -> 136.77432 | E12: =MAIZ!K10 -> 122.0145 | F12: =GIRASOL!K10 -> 244.98346 | K12: =+C12*C$2+D12*D$2+E12*E$2+F12*F$2 -> 196.94602 | L12: =+L11 -> 178.61766 | M12: =+M11 -> 266.24122 | N12: S
A13: 34243 | B13: O | C13: =SOJA!K11 -> 217.78709 | D13: =TRIGO!K11 -> 131.89448 | E13: =MAIZ!K11 -> 127.0095 | F13: =GIRASOL!K11 -> 240.41433 | K13: =+C13*C$2+D13*D$2+E13*E$2+F13*F$2 -> 190.55581 | L13: =+L12 -> 178.61766 | M13: =+M12 -> 266.24122 | N13: O
A14: 34274 | B14: N | C14: =SOJA!K12 -> 227.80031 | D14: =TRIGO!K12 -> 124.8595 | E14: =MAIZ!K12 -> 130.71229 | F14: =GIRASOL!K12 -> 245.68546 | K14: =+C14*C$2+D14*D$2+E14*E$2+F14*F$2 -> 196.68365 | L14: =+L13 -> 178.61766 | M14: =+M13 -> 266.24122 | N14: N
A15: 34304 | B15: D-93 | C15: =SOJA!K13 -> 228.78911 | D15: =TRIGO!K13 -> 120.00708 | E15: =MAIZ!K13 -> 132.69076 | F15: =GIRASOL!K13 -> 289.98785 | K15: =+C15*C$2+D15*D$2+E15*E$2+F15*F$2 -> 199.42135 | L15: =+L14 -> 178.61766 | M15: =+M14 -> 266.24122 | N15: D-93
A16: 34335 | B16: E-94 | C16: =SOJA!K14 -> 231.37519 | D16: =TRIGO!K14 -> 116.95953 | E16: =MAIZ!K14 -> 123.78217 | F16: =GIRASOL!K14 -> 272.75938 | K16: =+C16*C$2+D16*D$2+E16*E$2+F16*F$2 -> 198.05649 | L16: =+L15 -> 178.61766 | M16: =+M15 -> 266.24122 | N16: E-94 | R16: 120.75238
A17: 34366 | B17: F | C17: =SOJA!K15 -> 223.95367 | D17: =TRIGO!K15 -> 113.11284 | E17: =MAIZ!K15 -> 112.13773 | F17: =GIRASOL!K15 -> 256.88803 | K17: =+C17*C$2+D17*D$2+E17*E$2+F17*F$2 -> 189.95154 | L17: =+L16 -> 178.61766 | M17: =+M16 -> 266.24122 | N17: F | R17: 110.305
A18: 34394 | B18: M | C18: =SOJA!K16 -> 224.92605 | D18: =TRIGO!K16 -> 114.10388 | E18: =MAIZ!K16 -> 105.32666 | F18: =GIRASOL!K16 -> 253.15945 | K18: =+C18*C$2+D18*D$2+E18*E$2+F18*F$2 -> 189.30591 | L18: =+L17 -> 178.61766 | M18: =+M17 -> 266.24122 | N18: M | R18: 103.74545
A19: 34425 | B19: A | C19: =SOJA!K17 -> 214.96963 | D19: =TRIGO!K17 -> 118.67907 | E19: =MAIZ!K17 -> 103.1146 | F19: =GIRASOL!K17 -> 236.56047 | K19: =+C19*C$2+D19*D$2+E19*E$2+F19*F$2 -> 182.47164 | L19: =+L18 -> 178.61766 | M19: =+M18 -> 266.24122 | N19: A | R19: 100.66
A20: 34455 | B20: M | C20: =SOJA!K18 -> 222.31136 | D20: =TRIGO!K18 -> 124.86683 | E20: =MAIZ!K18 -> 105.50763 | F20: =GIRASOL!K18 -> 247.53156 | K20: =+C20*C$2+D20*D$2+E20*E$2+F20*F$2 -> 188.98514 | L20: =+L19 -> 178.61766 | M20: =+M19 -> 266.24122 | N20: M | R20: 107.75238
A21: 34486 | B21: J | C21: =SOJA!K19 -> 224.94545 | D21: =TRIGO!K19 -> 126.18445 | E21: =MAIZ!K19 -> 105.9564 | F21: =GIRASOL!K19 -> 246.32456 | K21: =+C21*C$2+D21*D$2+E21*E$2+F21*F$2 -> 190.82766 | L21: =+L20 -> 178.61766 | M21: =+M20 -> 266.24122 | N21: J | R21: 108.615
A22: 34516 | B22: J | C22: =SOJA!K20 -> 207.30647 | D22: =TRIGO!K20 -> 125.0761 | E22: =MAIZ!K20 -> 98.342276 | F22: =GIRASOL!K20 -> 230.34053 | K22: =+C22*C$2+D22*D$2+E22*E$2+F22*F$2 -> 177.47082 | L22: =+L21 -> 178.61766 | M22: =+M21 -> 266.24122 | N22: J | R22: 103.53333
A23: 34547 | B23: A | C23: =SOJA!K21 -> 206.3408 | D23: =TRIGO!K21 -> 122.59281 | E23: =MAIZ!K21 -> 95.983515 | F23: =GIRASOL!K21 -> 224.6822 | K23: =+C23*C$2+D23*D$2+E23*E$2+F23*F$2 -> 175.77392 | L23: =+L22 -> 178.61766 | M23: =+M22 -> 266.24122 | N23: A | R23: 99.618182
A24: 34578 | B24: S | C24: =SOJA!K22 -> 211.07741 | D24: =TRIGO!K22 -> 132.5655 | E24: =MAIZ!K22 -> 104.1586 | F24: =GIRASOL!K22 -> 223.86998 | K24: =+C24*C$2+D24*D$2+E24*E$2+F24*F$2 -> 181.57068 | L24: =+L23 -> 178.61766 | M24: =+M23 -> 266.24122 | N24: S | R24: 107.98636
A25: 34608 | B25: O | C25: =SOJA!K23 -> 209.45829 | D25: =TRIGO!K23 -> 144.38891 | E25: =MAIZ!K23 -> 109.47133 | F25: =GIRASOL!K23 -> 218.56517 | K25: =+C25*C$2+D25*D$2+E25*E$2+F25*F$2 -> 182.93778 | L25: =+L24 -> 178.61766 | M25: =+M24 -> 266.24122 | N25: O | R25: 114.745
A26: 34639 | B26: N | C26: =SOJA!K24 -> 205.7919 | D26: =TRIGO!K24 -> 144.37232 | E26: =MAIZ!K24 -> 116.06402 | F26: =GIRASOL!K24 -> 227.6459 | K26: =+C26*C$2+D26*D$2+E26*E$2+F26*F$2 -> 182.31589 | L26: =+L25 -> 178.61766 | M26: =+M25 -> 266.24122 | N26: N | R26: 117.43182
A27: 34669 | B27: D-94 | C27: =SOJA!K25 -> 206.46353 | D27: =TRIGO!K25 -> 128.1826 | E27: =MAIZ!K25 -> 120.64245 | F27: =GIRASOL!K25 -> 224.65415 | K27: =+C27*C$2+D27*D$2+E27*E$2+F27*F$2 -> 180.97051 | L27: =+L26 -> 178.61766 | M27: =+M26 -> 266.24122 | N27: D-94 | R27: 124.44
... A39: 35034 | B39: D-95 | C39: =SOJA!K37 -> 243.05665 | D39: =TRIGO!K37 -> 200.01614 | E39: =MAIZ!K37 -> 134.2701 | F39: =GIRASOL!K37 -> 220.71689 | K39: =+C39*C$2+D39*D$2+E39*E$2+F39*F$2 -> 216.48678 | L39: =+L38 -> 178.61766 | M39: =+M38 -> 266.24122 | N39: D-95 | R39: 137.56111
A40: 35065 | B40: E-96 | C40: =SOJA!K38 -> 244.78282 | D40: =TRIGO!K38 -> 205.69597 | E40: =MAIZ!K38 -> 141.12773 | F40: =GIRASOL!K38 -> 218.07924 | K40: =+C40*C$2+D40*D$2+E40*E$2+F40*F$2 -> 219.44531 | L40: =+L39 -> 178.61766 | M40: =+M39 -> 266.24122 | N40: E-96 | O40: 131.21308 | P40: =+AVERAGE(O40:O111) -> 94.614975 | Q40: =+AVERAGE(O112:O280) -> 141.16194 | R40: 148.6
A41: 35096 | B41: F | C41: =SOJA!K39 -> 243.83803 | D41: =TRIGO!K39 -> 224.91466 | E41: =MAIZ!K39 -> 149.9431 | F41: =GIRASOL!K39 -> 211.68357 | K41: =+C41*C$2+D41*D$2+E41*E$2+F41*F$2 -> 222.87309 | L41: =+L40 -> 178.61766 | M41: =+M40 -> 266.24122 | N41: F | O41: 144.34737 | P41: =+P40 -> 94.614975 | Q41: =+Q40 -> 141.16194 | R41: 160.29524
A42: 35125 | B42: M | C42: =SOJA!K40 -> 240.80928 | D42: =TRIGO!K40 -> 229.0584 | E42: =MAIZ!K40 -> 153.63673 | F42: =GIRASOL!K40 -> 209.36031 | K42: =+C42*C$2+D42*D$2+E42*E$2+F42*F$2 -> 222.11497 | L42: =+L41 -> 178.61766 | M42: =+M41 -> 266.24122 | N42: M | O42: 145.9964 | P42: =+P41 -> 94.614975 | Q42: =+Q41 -> 141.16194 | R42: 156.39524
A43: 35156 | B43: A | C43: =SOJA!K41 -> 260.39826 | D43: =TRIGO!K41 -> 245.64996 | E43: =MAIZ!K41 -> 174.93255 | F43: =GIRASOL!K41 -> 221.78749 | K43: =+C43*C$2+D43*D$2+E43*E$2+F43*F$2 -> 241.15506 | L43: =+L42 -> 178.61766 | M43: =+M42 -> 266.24122 | N43: A | O43: 167.00999 | P43: =+P42 -> 94.614975 | Q43: =+Q42 -> 141.16194
A44: 35186 | B44: M | C44: =SOJA!K42 -> 264.43714 | D44: =TRIGO!K42 -> 264.70744 | E44: =MAIZ!K42 -> 183.61749 | F44: =GIRASOL!K42 -> 236.55431 | K44: =+C44*C$2+D44*D$2+E44*E$2+F44*F$2 -> 248.82662 | L44: =+L43 -> 178.61766 | M44: =+M43 -> 266.24122 | N44: M | O44: 175.33256 | P44: =+P43 -> 94.614975 | Q44: =+Q43 -> 141.16194
A45: 35217 | B45: J | C45: =SOJA!K43 -> 255.58931 | D45: =TRIGO!K43 -> 245.27471 | E45: =MAIZ!K43 -> 173.46425 | F45: =GIRASOL!K43 -> 239.38998 | K45: =+C45*C$2+D45*D$2+E45*E$2+F45*F$2 -> 238.84546 | L45: =+L44 -> 178.61766 | M45: =+M44 -> 266.24122 | N45: J | O45: 163.38971 | P45: =+P44 -> 94.614975 | Q45: =+Q44 -> 141.16194
A46: 35247 | B46: J | C46: =SOJA!K44 -> 255.29366 | D46: =TRIGO!K44 -> 216.28369 | E46: =MAIZ!K44 -> 168.94263 | F46: =GIRASOL!K44 -> 231.10795 | K46: =+C46*C$2+D46*D$2+E46*E$2+F46*F$2 -> 233.12396 | L46: =+L45 -> 178.61766 | M46: =+M45 -> 266.24122 | N46: J | O46: 158.93987 | P46: =+P45 -> 94.614975 | Q46: =+Q45 -> 141.16194
A47: 35278 | B47: A | C47: =SOJA!K45 -> 264.39264 | D47: =TRIGO!K45 -> 193.18054 | E47: =MAIZ!K45 -> 161.60295 | F47: =GIRASOL!K45 -> 233.92027 | K47: =+C47*C$2+D47*D$2+E47*E$2+F47*F$2 -> 234.24704 | L47: =+L46 -> 178.61766 | M47: =+M46 -> 266.24122 | N47: A | O47: 150.21339 | P47: =+P46 -> 94.614975 | Q47: =+Q46 -> 141.16194
A48: 35309 | B48: S | C48: =SOJA!K46 -> 276.18305 | D48: =TRIGO!K46 -> 165.79226 | E48: =MAIZ!K46 -> 144.48935 | F48: =GIRASOL!K46 -> 235.06842 | K48: =+C48*C$2+D48*D$2+E48*E$2+F48*F$2 -> 234.61377 | L48: =+L47 -> 178.61766 | M48: =+M47 -> 266.24122 | N48: S | O48: 134.62572 | P48: =+P47 -> 94.614975 | Q48: =+Q47 -> 141.16194
A49: 35339 | B49: O | C49: =SOJA!K47 -> 270.18977 | D49: =TRIGO!K47 -> 156.57302 | E49: =MAIZ!K47 -> 131.70554 | F49: =GIRASOL!K47 -> 216.86284 | K49: =+C49*C$2+D49*D$2+E49*E$2+F49*F$2 -> 226.273 | L49: =+L48 -> 178.61766 | M49: =+M48 -> 266.24122 | N49: O | O49: 116.29805 | P49: =+P48 -> 94.614975 | Q49: =+Q48 -> 141.16194
A50: 35370 | B50: N | C50: =SOJA!K48 -> 270.51142 | D50: =TRIGO!K48 -> 146.61616 | E50: =MAIZ!K48 -> 117.1085 | F50: =GIRASOL!K48 -> 210.00229 | K50: =+C50*C$2+D50*D$2+E50*E$2+F50*F$2 -> 222.07239 | L50: =+L49 -> 178.61766 | M50: =+M49 -> 266.24122 | N50: N | O50: 104.36323 | P50: =+P49 -> 94.614975 | Q50: =+Q49 -> 141.16194
A51: 35400 | B51: D-96 | C51: =SOJA!K49 -> 271.52671 | D51: =TRIGO!K49 -> 128.65494 | E51: =MAIZ!K49 -> 114.77131 | F51: =GIRASOL!K49 -> 209.89729 | K51: =+C51*C$2+D51*D$2+E51*E$2+F51*F$2 -> 219.6367 | L51: =+L50 -> 178.61766 | M51: =+M50 -> 266.24122 | N51: D-96 | O51: 98.988957 | P51: =+P50 -> 94.614975 | Q51: =+Q50 -> 141.16194
A52: 35431 | B52: E-97 | C52: =SOJA!K50 -> 268.16421 | D52: =TRIGO!K50 -> 132.50402 | E52: =MAIZ!K50 -> 105.81918 | F52: =GIRASOL!K50 -> 207.78287 | K52: =+C52*C$2+D52*D$2+E52*E$2+F52*F$2 -> 216.43623 | L52: =+L51 -> 178.61766 | M52: =+M51 -> 266.24122 | N52: E-97 | O52: 95.010251 | P52: =+P51 -> 94.614975 | Q52: =+Q51 -> 141.16194
...

Sheet SOJA
C1: FOB USD/Ton | D1: com3500 $/USD | E1: IPC 1993=1 | F1: INDICE FOB*FX/IPC todo base 1993 (1) | G1: FX 1993=1 | H1: Precio FOB*FX/(IPC 1993=1) = FOB REAL | I1: DEX | J1: (1)*(1-DEX) | K1: FOB REAL*(1-DEX) = PRP
A2: 33970 | B2: E-93 | C2: 221 | D2: 0.99874 | E2: ='[1]IPC99ON (real)'!O152 -> 0.96122511 | F2: =+(C2*(D2/E2))/(AVERAGE(C$2:C$13)*AVERAGE(D$2:D$13)/AVERAGE(E$2:E$13))*100 -> 101.11126 | G2: =+E2/AVERAGE(E$2:E$13) -> 0.96122511 | H2: =+(C2*D2)/G2 -> 229.62523 | I2: =+I3 -> 0.035 | J2: =+F2*(1-I2) -> 97.572371 | K2: =+H2*(1-I2) -> 221.58835 | L2: =+AVERAGE(K2:K109) -> 206.90372 | M2: =+AVERAGE(K110:K277) -> 304.63353
A3: 34001 | B3: F | C3: 205 | D3: 0.999155 | E3: ='[1]IPC99ON (real)'!O153 -> 0.96824627 | F3: =+(C3*(D3/E3))/(AVERAGE(C$2:C$13)*AVERAGE(D$2:D$13)/AVERAGE(E$2:E$13))*100 -> 93.149564 | G3: =+E3/AVERAGE(E$2:E$13) -> 0.96824627 | H3: =+(C3*D3)/G3 -> 211.54409 | I3: =+I4 -> 0.035 | J3: =+F3*(1-I3) -> 89.889329 | K3: =+H3*(1-I3) -> 204.14005 | L3: =+L2 -> 206.90372 | M3: =+M2 -> 304.63353
A4: 34029 | B4: M | C4: 204 | D4: 0.999687 | E4: ='[1]IPC99ON (real)'!O154 -> 0.97552607 | F4: =+(C4*(D4/E4))/(AVERAGE(C$2:C$13)*AVERAGE(D$2:D$13)/AVERAGE(E$2:E$13))*100 -> 92.052432 | G4: =+E4/AVERAGE(E$2:E$13) -> 0.97552607 | H4: =+(C4*D4)/G4 -> 209.05248 | I4: =+I5 -> 0.035 | J4: =+F4*(1-I4) -> 88.830597 | K4: =+H4*(1-I4) -> 201.73565 | L4: =+L3 -> 206.90372 | M4: =+M3 -> 304.63353
A5: 34060 | B5: A | C5: 208 | D5: 0.99916 | E5: ='[1]IPC99ON (real)'!O155 -> 0.98572347 | F5: =+(C5*(D5/E5))/(AVERAGE(C$2:C$13)*AVERAGE(D$2:D$13)/AVERAGE(E$2:E$13))*100 -> 92.837451 | G5: =+E5/AVERAGE(E$2:E$13) -> 0.98572347 | H5: =+(C5*D5)/G5 -> 210.83528 | I5: =+I6 -> 0.035 | J5: =+F5*(1-I5) -> 89.588141 | K5: =+H5*(1-I5) -> 203.45604 | L5: =+L4 -> 206.90372 | M5: =+M4 -> 304.63353
A6: 34090 | B6: M | C6: 213 | D6: 0.999395 | E6: ='[1]IPC99ON (real)'!O156 -> 0.99840532 | F6: =+(C6*(D6/E6))/(AVERAGE(C$2:C$13)*AVERAGE(D$2:D$13)/AVERAGE(E$2:E$13))*100 -> 93.883619 | G6: =+E6/AVERAGE(E$2:E$13) -> 0.99840532 | H6: =+(C6*D6)/G6 -> 213.21114 | I6: =+I7 -> 0.035 | J6: =+F6*(1-I6) -> 90.597692 | K6: =+H6*(1-I6) -> 205.74875 | L6: =+L5 -> 206.90372 | M6: =+M5 -> 304.63353
A7: 34121 | B7: J | C7: 218 | D7: 0.9992857 | E7: ='[1]IPC99ON (real)'!O157 -> 1.005587 | F7: =+(C7*(D7/E7))/(AVERAGE(C$2:C$13)*AVERAGE(D$2:D$13)/AVERAGE(E$2:E$13))*100 -> 95.390795 | G7: =+E7/AVERAGE(E$2:E$13) -> 1.005587 | H7: =+(C7*D7)/G7 -> 216.63396 | I7: =+I8 -> 0.035 | J7: =+F7*(1-I7) -> 92.052117 | K7: =+H7*(1-I7) -> 209.05177 | L7: =+L6 -> 206.90372 | M7: =+M6 -> 304.63353
A8: 34151 | B8: J | C8: 253 | D8: 0.9989238 | E8: ='[1]IPC99ON (real)'!O158 -> 1.0088218 | F8: =+(C8*(D8/E8))/(AVERAGE(C$2:C$13)*AVERAGE(D$2:D$13)/AVERAGE(E$2:E$13))*100 -> 110.31088 | G8: =+E8/AVERAGE(E$2:E$13) -> 1.0088218 | H8: =+(C8*D8)/G8 -> 250.5177 | I8: =+I9 -> 0.035 | J8: =+F8*(1-I8) -> 106.45 | K8: =+H8*(1-I8) -> 241.74958 | L8: =+L7 -> 206.90372 | M8: =+M7 -> 304.63353
A9: 34182 | B9: A | C9: 249 | D9: 1.000175 | E9: ='[1]IPC99ON (real)'!O159 -> 1.0089836 | F9: =+(C9*(D9/E9))/(AVERAGE(C$2:C$13)*AVERAGE(D$2:D$13)/AVERAGE(E$2:E$13))*100 -> 108.68539 | G9: =+E9/AVERAGE(E$2:E$13) -> 1.0089836 | H9: =+(C9*D9)/G9 -> 246.82618 | I9: =+I10 -> 0.035 | J9: =+F9*(1-I9) -> 104.8814 | K9: =+H9*(1-I9) -> 238.18726 | L9: =+L8 -> 206.90372 | M9: =+M8 -> 304.63353
A10: 34213 | B10: S | C10: 240 | D10: 1.0010095 | E10: ='[1]IPC99ON (real)'!O160 -> 1.0172986 | F10: =+(C10*(D10/E10))/(AVERAGE(C$2:C$13)*AVERAGE(D$2:D$13)/AVERAGE(E$2:E$13))*100 -> 103.98745 | G10: =+E10/AVERAGE(E$2:E$13) -> 1.0172986 | H10: =+(C10*D10)/G10 -> 236.15709 | I10: =+I11 -> 0.035 | J10: =+F10*(1-I10) -> 100.34789 | K10: =+H10*(1-I10) -> 227.89159 | L10: =+L9 -> 206.90372 | M10: =+M9 -> 304.63353
A11: 34243 | B11: O | C11: 231 | D11: 0.999515 | E11: ='[1]IPC99ON (real)'!O161 -> 1.0230491 | F11: =+(C11*(D11/E11))/(AVERAGE(C$2:C$13)*AVERAGE(D$2:D$13)/AVERAGE(E$2:E$13))*100 -> 99.376744 | G11: =+E11/AVERAGE(E$2:E$13) -> 1.0230491 | H11: =+(C11*D11)/G11 -> 225.68611 | I11: =+I12 -> 0.035 | J11: =+F11*(1-I11) -> 95.898558 | K11: =+H11*(1-I11) -> 217.78709 | L11: =+L10 -> 206.90372 | M11: =+M10 -> 304.63353
A12: 34274 | B12: N | C12: 242 | D12: 0.998519 | E12: ='[1]IPC99ON (real)'!O162 -> 1.023634 | F12: =+(C12*(D12/E12))/(AVERAGE(C$2:C$13)*AVERAGE(D$2:D$13)/AVERAGE(E$2:E$13))*100 -> 103.9458 | G12: =+E12/AVERAGE(E$2:E$13) -> 1.023634 | H12: =+(C12*D12)/G12 -> 236.0625 | I12: =+I13 -> 0.035 | J12: =+F12*(1-I12) -> 100.30769 | K12: =+H12*(1-I12) -> 227.80031 | L12: =+L11 -> 206.90372 | M12: =+M11 -> 304.63353
A13: 34304 | B13: D-93 | C13: 243 | D13: 0.9985952 | E13: ='[1]IPC99ON (real)'!O163 -> 1.0234997 | F13: =+(C13*(D13/E13))/(AVERAGE(C$2:C$13)*AVERAGE(D$2:D$13)/AVERAGE(E$2:E$13))*100 -> 104.39699 | G13: =+E13/AVERAGE(E$2:E$13) -> 1.0234997 | H13: =+(C13*D13)/G13 -> 237.08716 | I13: =+I14 -> 0.035 | J13: =+F13*(1-I13) -> 100.74309 | K13: =+H13*(1-I13) -> 228.78911 | L13: =+L12 -> 206.90372 | M13: =+M12 -> 304.63353
A14: 34335 | B14: E-94 | C14: 246 | D14: 0.9985714 | E14: ='[1]IPC99ON (real)'!O164 -> 1.0245302 | F14: =+(C14*(D14/E14))/(AVERAGE(C$2:C$13)*AVERAGE(D$2:D$13)/AVERAGE(E$2:E$13))*100 -> 105.57702 | G14: =+E14/AVERAGE(E$2:E$13) -> 1.0245302 | H14: =+(C14*D14)/G14 -> 239.76704 | I14: =+I15 -> 0.035 | J14: =+F14*(1-I14) -> 101.88183 | K14: =+H14*(1-I14) -> 231.37519 | L14: =+L13 -> 206.90372 | M14: =+M13 -> 304.63353
... A97: 36861 | B97: D-00 | C97: 205 | D97: 1.0004278 | E97: ='[1]IPC99ON (real)'!O247 -> 1.0637525 | F97: =+(C97*(D97/E97))/(AVERAGE(C$2:C$13)*AVERAGE(D$2:D$13)/AVERAGE(E$2:E$13))*100 -> 84.894377 | G97: =+E97/AVERAGE(E$2:E$13) -> 1.0637525 | H97: =+(C97*D97)/G97 -> 192.79643 | I97: =+I98 -> 0.035 | J97: =+F97*(1-I97) -> 81.923074 | K97: =+H97*(1-I97) -> 186.04856 | L97: =+L96 -> 206.90372 | M97: =+M96 -> 304.63353
A98: 36892 | B98: E-01 | C98: 206 | D98: 0.99966818 | E98: ='[1]IPC99ON (real)'!O248 -> 1.064611 | F98: =+(C98*(D98/E98))/(AVERAGE(C$2:C$13)*AVERAGE(D$2:D$13)/AVERAGE(E$2:E$13))*100 -> 85.174985 | G98: =+E98/AVERAGE(E$2:E$13) -> 1.064611 | H98: =+(C98*D98)/G98 -> 193.4337 | I98: 0.035 | J98: =+F98*(1-I98) -> 82.193861 | K98: =+H98*(1-I98) -> 186.66352 | L98: =+L97 -> 206.90372 | M98: =+M97 -> 304.63353
A99: 36923 | B99: F | C99: 187 | D99: 0.99899 | E99: ='[1]IPC99ON (real)'!O249 -> 1.0622502 | F99: =+(C99*(D99/E99))/(AVERAGE(C$2:C$13)*AVERAGE(D$2:D$13)/AVERAGE(E$2:E$13))*100 -> 77.438307 | G99: =+E99/AVERAGE(E$2:E$13) -> 1.0622502 | H99: =+(C99*D99)/G99 -> 175.86358 | I99: 0.035 | J99: =+F99*(1-I99) -> 74.727967 | K99: =+H99*(1-I99) -> 169.70836 | L99: =+L98 -> 206.90372 | M99: =+M98 -> 304.63353
A100: 36951 | B100: M | C100: 178 | D100: 1.0035 | E100: ='[1]IPC99ON (real)'!O250 -> 1.0642891 | F100: =+(C100*(D100/E100))/(AVERAGE(C$2:C$13)*AVERAGE(D$2:D$13)/AVERAGE(E$2:E$13))*100 -> 73.902257 | G100: =+E100/AVERAGE(E$2:E$13) -> 1.0642891 | H100: =+(C100*D100)/G100 -> 167.83316 | I100: 0.035 | J100: =+F100*(1-I100) -> 71.315678 | K100: =+H100*(1-I100) -> 161.959 | L100: =+L99 -> 206.90372 | M100: =+M99 -> 304.63353
A101: 36982 | B101: A | C101: 153 | D101: 1.0000222 | E101: ='[1]IPC99ON (real)'!O251 -> 1.0713715 | F101: =+(C101*(D101/E101))/(AVERAGE(C$2:C$13)*AVERAGE(D$2:D$13)/AVERAGE(E$2:E$13))*100 -> 62.884113 | G101: =+E101/AVERAGE(E$2:E$13) -> 1.0713715 | H101: =+(C101*D101)/G101 -> 142.81078 | I101: 0.035 | J101: =+F101*(1-I101) -> 60.683169 | K101: =+H101*(1-I101) -> 137.81241 | L101: =+L100 -> 206.90372 | M101: =+M100 -> 304.63353
A102: 37012 | B102: M | C102: 157 | D102: 0.99949524 | E102: ='[1]IPC99ON (real)'!O252 -> 1.0720153 | F102: =+(C102*(D102/E102))/(AVERAGE(C$2:C$13)*AVERAGE(D$2:D$13)/AVERAGE(E$2:E$13))*100 -> 64.455402 | G102: =+E102/AVERAGE(E$2:E$13) -> 1.0720153 | H102: =+(C102*D102)/G102 -> 146.37921 | I102: 0.035 | J102: =+F102*(1-I102) -> 62.199463 | K102: =+H102*(1-I102) -> 141.25593 | L102: =+L101 -> 206.90372 | M102: =+M101 -> 304.63353
A103: 37043 | B103: J | C103: 166 | D103: 0.99989 | E103: ='[1]IPC99ON (real)'!O253 -> 1.0642891 | F103: =+(C103*(D103/E103))/(AVERAGE(C$2:C$13)*AVERAGE(D$2:D$13)/AVERAGE(E$2:E$13))*100 -> 68.672149 | G103: =+E103/AVERAGE(E$2:E$13) -> 1.0642891 | H103: =+(C103*D103)/G103 -> 155.9555 | I103: 0.035 | J103: =+F103*(1-I103) -> 66.268624 | K103: =+H103*(1-I103) -> 150.49706 | L103: =+L102 -> 206.90372 | M103: =+M102 -> 304.63353
A104: 37073 | B104: J | C104: 188 | D104: 1.0063952 | E104: ='[1]IPC99ON (real)'!O254 -> 1.0608552 | F104: =+(C104*(D104/E104))/(AVERAGE(C$2:C$13)*AVERAGE(D$2:D$13)/AVERAGE(E$2:E$13))*100 -> 78.532649 | G104: =+E104/AVERAGE(E$2:E$13) -> 1.0608552 | H104: =+(C104*D104)/G104 -> 178.34885 | I104: 0.035 | J104: =+F104*(1-I104) -> 75.784006 | K104: =+H104*(1-I104) -> 172.10664 | L104: =+L103 -> 206.90372 | M104: =+M103 -> 304.63353
A105: 37104 | B105: A | C105: 189 | D105: 1.0005391 | E105: ='[1]IPC99ON (real)'!O255 -> 1.0570994 | F105: =+(C105*(D105/E105))/(AVERAGE(C$2:C$13)*AVERAGE(D$2:D$13)/AVERAGE(E$2:E$13))*100 -> 78.769845 | G105: =+E105/AVERAGE(E$2:E$13) -> 1.0570994 | H105: =+(C105*D105)/G105 -> 178.88753 | I105: 0.035 | J105: =+F105*(1-I105) -> 76.0129 | K105: =+H105*(1-I105) -> 172.62646 | L105: =+L104 -> 206.90372 | M105: =+M104 -> 304.63353
A106: 37135 | B106: S | C106: 180 | D106: 0.999805 | E106: ='[1]IPC99ON (real)'!O256 -> 1.0562409 | F106: =+(C106*(D106/E106))/(AVERAGE(C$2:C$13)*AVERAGE(D$2:D$13)/AVERAGE(E$2:E$13))*100 -> 75.024784 | G106: =+E106/AVERAGE(E$2:E$13) -> 1.0562409 | H106: =+(C106*D106)/G106 -> 170.38243 | I106: 0.035 | J106: =+F106*(1-I106) -> 72.398916 | K106: =+H106*(1-I106) -> 164.41905 | L106: =+L105 -> 206.90372 | M106: =+M105 -> 304.63353
A107: 37165 | B107: O | C107: 172 | D107: 1.002413 | E107: ='[1]IPC99ON (real)'!O257 -> 1.0516266 | F107: =+(C107*(D107/E107))/(AVERAGE(C$2:C$13)*AVERAGE(D$2:D$13)/AVERAGE(E$2:E$13))*100 -> 72.192737 | G107: =+E107/AVERAGE(E$2:E$13) -> 1.0516266 | H107: =+(C107*D107)/G107 -> 163.95081 | I107: 0.035 | J107: =+F107*(1-I107) -> 69.665991 | K107: =+H107*(1-I107) -> 158.21253 | L107: =+L106 -> 206.90372 | M107: =+M106 -> 304.63353
A108: 37196 | B108: N | C108: 178 | D108: 1.0039409 | E108: ='[1]IPC99ON (real)'!O258 -> 1.0481928 | F108: =+(C108*(D108/E108))/(AVERAGE(C$2:C$13)*AVERAGE(D$2:D$13)/AVERAGE(E$2:E$13))*100 -> 75.070089 | G108: =+E108/AVERAGE(E$2:E$13) -> 1.0481928 | H108: =+(C108*D108)/G108 -> 170.48532 | I108: 0.035 | J108: =+F108*(1-I108) -> 72.442636 | K108: =+H108*(1-I108) -> 164.51834 | L108: =+L107 -> 206.90372 | M108: =+M107 -> 304.63353
A109: 37226 | B109: D-01 | C109: 179 | D109: 1.0546 | E109: ='[1]IPC99ON (real)'!O259 -> 1.0473343 | F109: =+(C109*(D109/E109))/(AVERAGE(C$2:C$13)*AVERAGE(D$2:D$13)/AVERAGE(E$2:E$13))*100 -> 79.36617 | G109: =+E109/AVERAGE(E$2:E$13) -> 1.0473343 | H109: =+(C109*D109)/G109 -> 180.24179 | I109: 0.035 | J109: =+F109*(1-I109) -> 76.588354 | K109: =+H109*(1-I109) -> 173.93333 | L109: =+L108 -> 206.90372 | M109: =+M108 -> 304.63353
... A282: 42491 | B282: M | C282: 400.57 | D282: 14.137724 | E282: ='[1]IPC99ON (real)'!O432 -> 17.902634 | F282: =+(C282*(D282/E282))/(AVERAGE(C$2:C$13)*AVERAGE(D$2:D$13)/AVERAGE(E$2:E$13))*100 -> 139.29031 | G282: =+E282/AVERAGE(E$2:E$13) -> 17.902634 | H282: =+(C282*D282)/G282 -> 316.33044 | I282: 0.3 | J282: =+F282*(1-I282) -> 97.50322 | K282: =+H282*(1-I282) -> 221.43131 | L282: =+L281 -> 206.90372 | M282: =+M281 -> 304.63353
A283: 42522 | B283: J | C283: 441.53 | D283: 14.1408 | E283: ='[1]IPC99ON (real)'!O433 -> 18.453286 | F283: =+(C283*(D283/E283))/(AVERAGE(C$2:C$13)*AVERAGE(D$2:D$13)/AVERAGE(E$2:E$13))*100 -> 148.98427 | G283: =+E283/AVERAGE(E$2:E$13) -> 18.453286 | H283: =+(C283*D283)/G283 -> 338.34555 | I283: =+I282 -> 0.3 | J283: =+F283*(1-I283) -> 104.28899 | K283: =+H283*(1-I283) -> 236.84189 | L283: =+L282 -> 206.90372 | M283: =+M282 -> 304.63353
A284: 42552 | B284: J | C284: 427.1 | D284: 14.909385 | E284: ='[1]IPC99ON (real)'!O434 -> 18.830984 | F284: =+(C284*(D284/E284))/(AVERAGE(C$2:C$13)*AVERAGE(D$2:D$13)/AVERAGE(E$2:E$13))*100 -> 148.90052 | G284: =+E284/AVERAGE(E$2:E$13) -> 18.830984 | H284: =+(C284*D284)/G284 -> 338.15537 | I284: =+I283 -> 0.3 | J284: =+F284*(1-I284) -> 104.23037 | K284: =+H284*(1-I284) -> 236.70876 | L284: =+L283 -> 206.90372 | M284: =+M283 -> 304.63353
A285: 42583 | B285: A | C285: 408.13636 | D285: 14.849809 | E285: ='[1]IPC99ON (real)'!O435 -> 18.869025 | F285: =+(C285*(D285/E285))/(AVERAGE(C$2:C$13)*AVERAGE(D$2:D$13)/AVERAGE(E$2:E$13))*100 -> 141.43492 | G285: =+E285/AVERAGE(E$2:E$13) -> 18.869025 | H285: =+(C285*D285)/G285 -> 321.20086 | I285: =+I284 -> 0.3 | J285: =+F285*(1-I285) -> 99.004441 | K285: =+H285*(1-I285) -> 224.8406 | L285: =+L284 -> 206.90372 | M285: =+M284 -> 304.63353
A286: 42614 | B286: S | C286: 396 | D286: 15.100736 | E286: ='[1]IPC99ON (real)'!O436 -> 19.085846 | F286: =+(C286*(D286/E286))/(AVERAGE(C$2:C$13)*AVERAGE(D$2:D$13)/AVERAGE(E$2:E$13))*100 -> 137.96274 | G286: =+E286/AVERAGE(E$2:E$13) -> 19.085846 | H286: =+(C286*D286)/G286 -> 313.31551 | I286: =+I285 -> 0.3 | J286: =+F286*(1-I286) -> 96.573921 | K286: =+H286*(1-I286) -> 219.32086 | L286: =+L285 -> 206.90372 | M286: =+M285 -> 304.63353
A287: 42644 | B287: O | C287: 386 | D287: 15.181 | E287: ='[1]IPC99ON (real)'!O437 -> 19.536155 | F287: =+(C287*(D287/E287))/(AVERAGE(C$2:C$13)*AVERAGE(D$2:D$13)/AVERAGE(E$2:E$13))*100 -> 132.0774 | G287: =+E287/AVERAGE(E$2:E$13) -> 19.536155 | H287: =+(C287*D287)/G287 -> 299.94981 | I287: =+I286 -> 0.3 | J287: =+F287*(1-I287) -> 92.454183 | K287: =+H287*(1-I287) -> 209.96487 | L287: =+L286 -> 206.90372 | M287: =+M286 -> 304.63353
A288: 42675 | B288: N | C288: 384 | D288: 15.3399 | E288: ='[1]IPC99ON (real)'!O438 -> 19.85234 | F288: =+(C288*(D288/E288))/(AVERAGE(C$2:C$13)*AVERAGE(D$2:D$13)/AVERAGE(E$2:E$13))*100 -> 130.65378 | G288: =+E288/AVERAGE(E$2:E$13) -> 19.85234 | H288: =+(C288*D288)/G288 -> 296.71673 | I288: =+I287 -> 0.3 | J288: =+F288*(1-I288) -> 91.457644 | K288: =+H288*(1-I288) -> 207.70171 | L288: =+L287 -> 206.90372 | M288: =+M287 -> 304.63353
A289: 42705 | B289: D-16 | C289: 386 | D289: 15.8296 | E289: ='[1]IPC99ON (real)'!O439 -> 20.090072 | F289: =+(C289*(D289/E289))/(AVERAGE(C$2:C$13)*AVERAGE(D$2:D$13)/AVERAGE(E$2:E$13))*100 -> 133.92316 | G289: =+E289/AVERAGE(E$2:E$13) -> 20.090072 | H289: =+(C289*D289)/G289 -> 304.14154 | I289: 0.3 | J289: =+F289*(1-I289) -> 93.74621 | K289: =+H289*(1-I289) -> 212.89908 | L289: =+L288 -> 206.90372 | M289: =+M288 -> 304.63353
A290: 42736 | B290: E-17 | C290: 391 | D290: =[2]Cuadro!C466 -> 14.4095 | E290: ='[1]IPC99ON (real)'!O440 -> 20.411513 | F290: =+(C290*(D290/E290))/(AVERAGE(C$2:C$13)*AVERAGE(D$2:D$13)/AVERAGE(E$2:E$13))*100 -> 121.54312 | G290: =+E290/AVERAGE(E$2:E$13) -> 20.411513 | H290: =+(C290*D290)/G290 -> 276.0263 | I290: =+I289 -> 0.3 | J290: =+F290*(1-I290) -> 85.080187 | K290: =+H290*(1-I290) -> 193.21841 | L290: =+L289 -> 206.90372 | M290: =+M289 -> 304.63353
A291: 42767 | B291: F | C291: 387 | D291: =[2]Cuadro!C467 -> 14.137724 | E291: ='[1]IPC99ON (real)'!O441 -> 20.840155 | F291: =+(C291*(D291/E291))/(AVERAGE(C$2:C$13)*AVERAGE(D$2:D$13)/AVERAGE(E$2:E$13))*100 -> 115.60309 | G291: =+E291/AVERAGE(E$2:E$13) -> 20.840155 | H291: =+(C291*D291)/G291 -> 262.53639 | I291: =+I290 -> 0.3 | J291: =+F291*(1-I291) -> 80.922163 | K291: =+H291*(1-I291) -> 183.77547 | L291: =+L290 -> 206.90372 | M291: =+M290 -> 304.63353
A292: 42795 | B292: M | C292: 375.54545 | D292: =[2]Cuadro!C468 -> 14.1408 | E292: ='[1]IPC99ON (real)'!O442 -> 21.340319 | F292: =+(C292*(D292/E292))/(AVERAGE(C$2:C$13)*AVERAGE(D$2:D$13)/AVERAGE(E$2:E$13))*100 -> 109.57602 | G292: =+E292/AVERAGE(E$2:E$13) -> 21.340319 | H292: =+(C292*D292)/G292 -> 248.84882 | I292: =+I291 -> 0.3 | J292: =+F292*(1-I292) -> 76.703213 | K292: =+H292*(1-I292) -> 174.19417 | L292: =+L291 -> 206.90372 | M292: =+M291 -> 304.63353
A293: 42826 | B293: A | C293: 352 | D293: =[2]Cuadro!C469 -> 14.909385 | E293: ='[1]IPC99ON (real)'!O443 -> 21.916508 | F293: =+(C293*(D293/E293))/(AVERAGE(C$2:C$13)*AVERAGE(D$2:D$13)/AVERAGE(E$2:E$13))*100 -> 105.44135 | G293: =+E293/AVERAGE(E$2:E$13) -> 21.916508 | H293: =+(C293*D293)/G293 -> 239.45893 | I293: =+I292 -> 0.3 | J293: =+F293*(1-I293) -> 73.808948 | K293: =+H293*(1-I293) -> 167.62125 | L293: =+L292 -> 206.90372 | M293: =+M292 -> 304.63353
A294: 42856 | B294: M | C294: 361 | D294: =[2]Cuadro!C470 -> 14.849809 | E294: ='[1]IPC99ON (real)'!O444 -> 22.223339 | F294: =+(C294*(D294/E294))/(AVERAGE(C$2:C$13)*AVERAGE(D$2:D$13)/AVERAGE(E$2:E$13))*100 -> 106.21814 | G294: =+E294/AVERAGE(E$2:E$13) -> 22.223339 | H294: =+(C294*D294)/G294 -> 241.22303 | I294: =+I293 -> 0.3 | J294: =+F294*(1-I294) -> 74.3527 | K294: =+H294*(1-I294) -> 168.85612 | L294: =+L293 -> 206.90372 | M294: =+M293 -> 304.63353
...

Sheet TRIGO
C1: FOB USD/Ton | D1: com3500 $/USD | E1: IPC 1993=1 | F1: INDICE FOB*FX/IPC todo base 1993 (1) | G1: FX 1993=1 | H1: Precio FOB*FX/(IPC 1993=1) = FOB REAL | I1: DEX | J1: (1)*(1-DEX) | K1: FOB REAL*(1-DEX) = PRP
A2: 33970 | B2: E-93 | C2: 126 | D2: =SOJA!D2 -> 0.99874 | E2: =SOJA!E2 -> 0.96122511 | F2: =+(C2*(D2/E2))/(AVERAGE(C$109)*AVERAGE(D$109)/AVERAGE(E$109))*100 -> 119.28036 | G2: =+E2/AVERAGE(E$2:E$13) -> 0.96122511 | H2: =+(C2*D2)/G2 -> 130.91755 | I2: 0 | J2: =+F2*(1-I2)/(F$109*(1-I$109))*100 -> 119.28036 | K2: =+H2*(1-I2) -> 130.91755 | L2: =+AVERAGE(K2:K109) -> 134.93063 | M2: =+AVERAGE(K110:K277) -> 207.19615
A3: 34001 | B3: F | C3: 128 | D3: =SOJA!D3 -> 0.999155 | E3: =SOJA!E3 -> 0.96824627 | F3: =+(C3*(D3/E3))/(AVERAGE(C$109)*AVERAGE(D$109)/AVERAGE(E$109))*100 -> 120.345 | G3: =+E3/AVERAGE(E$2:E$13) -> 0.96824627 | H3: =+(C3*D3)/G3 -> 132.08606 | I3: =+I2 -> 0 | J3: =+F3*(1-I3)/(F$109*(1-I$109))*100 -> 120.345 | K3: =+H3*(1-I3) -> 132.08606 | L3: =+L2 -> 134.93063 | M3: =+M2 -> 207.19615
A4: 34029 | B4: M | C4: 123 | D4: =SOJA!D4 -> 0.999687 | E4: =SOJA!E4 -> 0.97552607 | F4: =+(C4*(D4/E4))/(AVERAGE(C$109)*AVERAGE(D$109)/AVERAGE(E$109))*100 -> 114.84215 | G4: =+E4/AVERAGE(E$2:E$13) -> 0.97552607 | H4: =+(C4*D4)/G4 -> 126.04635 | I4: =+I3 -> 0 | J4: =+F4*(1-I4)/(F$109*(1-I$109))*100 -> 114.84215 | K4: =+H4*(1-I4) -> 126.04635 | L4: =+L3 -> 134.93063 | M4: =+M3 -> 207.19615
A5: 34060 | B5: A | C5: 127 | D5: =SOJA!D5 -> 0.99916 | E5: =SOJA!E5 -> 0.98572347 | F5: =+(C5*(D5/E5))/(AVERAGE(C$109)*AVERAGE(D$109)/AVERAGE(E$109))*100 -> 117.2883 | G5: =+E5/AVERAGE(E$2:E$13) -> 0.98572347 | H5: =+(C5*D5)/G5 -> 128.73115 | I5: =+I4 -> 0 | J5: =+F5*(1-I5)/(F$109*(1-I$109))*100 -> 117.2883 | K5: =+H5*(1-I5) -> 128.73115 | L5: =+L4 -> 134.93063 | M5: =+M4 -> 207.19615
A6: 34090 | B6: M | C6: 133 | D6: =SOJA!D6 -> 0.999395 | E6: =SOJA!E6 -> 0.99840532 | F6: =+(C6*(D6/E6))/(AVERAGE(C$109)*AVERAGE(D$109)/AVERAGE(E$109))*100 -> 121.29781 | G6: =+E6/AVERAGE(E$2:E$13) -> 0.99840532 | H6: =+(C6*D6)/G6 -> 133.13184 | I6: =+I5 -> 0 | J6: =+F6*(1-I6)/(F$109*(1-I$109))*100 -> 121.29781 | K6: =+H6*(1-I6) -> 133.13184 | L6: =+L5 -> 134.93063 | M6: =+M5 -> 207.19615
A7: 34121 | B7: J | C7: 137 | D7: =SOJA!D7 -> 0.9992857 | E7: =SOJA!E7 -> 1.005587 | F7: =+(C7*(D7/E7))/(AVERAGE(C$109)*AVERAGE(D$109)/AVERAGE(E$109))*100 -> 124.03997 | G7: =+E7/AVERAGE(E$2:E$13) -> 1.005587 | H7: =+(C7*D7)/G7 -> 136.14152 | I7: =+I6 -> 0 | J7: =+F7*(1-I7)/(F$109*(1-I$109))*100 -> 124.03997 | K7: =+H7*(1-I7) -> 136.14152 | L7: =+L6 -> 134.93063 | M7: =+M6 -> 207.19615
A8: 34151 | B8: J | C8: 137 | D8: =SOJA!D8 -> 0.9989238 | E8: =SOJA!E8 -> 1.0088218 | F8: =+(C8*(D8/E8))/(AVERAGE(C$109)*AVERAGE(D$109)/AVERAGE(E$109))*100 -> 123.59745 | G8: =+E8/AVERAGE(E$2:E$13) -> 1.0088218 | H8: =+(C8*D8)/G8 -> 135.65583 | I8: =+I7 -> 0 | J8: =+F8*(1-I8)/(F$109*(1-I$109))*100 -> 123.59745 | K8: =+H8*(1-I8) -> 135.65583 | L8: =+L7 -> 134.93063 | M8: =+M7 -> 207.19615
A9: 34182 | B9: A | C9: 136 | D9: =SOJA!D9 -> 1.000175 | E9: =SOJA!E9 -> 1.0089836 | F9: =+(C9*(D9/E9))/(AVERAGE(C$109)*AVERAGE(D$109)/AVERAGE(E$109))*100 -> 122.82926 | G9: =+E9/AVERAGE(E$2:E$13) -> 1.0089836 | H9: =+(C9*D9)/G9 -> 134.81269 | I9: =+I8 -> 0 | J9: =+F9*(1-I9)/(F$109*(1-I$109))*100 -> 122.82926 | K9: =+H9*(1-I9) -> 134.81269 | L9: =+L8 -> 134.93063 | M9: =+M8 -> 207.19615
A10: 34213 | B10: S | C10: 139 | D10: =SOJA!D10 -> 1.0010095 | E10: =SOJA!E10 -> 1.0172986 | F10: =+(C10*(D10/E10))/(AVERAGE(C$109)*AVERAGE(D$109)/AVERAGE(E$109))*100 -> 124.61651 | G10: =+E10/AVERAGE(E$2:E$13) -> 1.0172986 | H10: =+(C10*D10)/G10 -> 136.77432 | I10: =+I9 -> 0 | J10: =+F10*(1-I10)/(F$109*(1-I$109))*100 -> 124.61651 | K10: =+H10*(1-I10) -> 136.77432 | L10: =+L9 -> 134.93063 | M10: =+M9 -> 207.19615
A11: 34243 | B11: O | C11: 135 | D11: =SOJA!D11 -> 0.999515 | E11: =SOJA!E11 -> 1.0230491 | F11: =+(C11*(D11/E11))/(AVERAGE(C$109)*AVERAGE(D$109)/AVERAGE(E$109))*100 -> 120.17044 | G11: =+E11/AVERAGE(E$2:E$13) -> 1.0230491 | H11: =+(C11*D11)/G11 -> 131.89448 | I11: =+I10 -> 0 | J11: =+F11*(1-I11)/(F$109*(1-I$109))*100 -> 120.17044 | K11: =+H11*(1-I11) -> 131.89448 | L11: =+L10 -> 134.93063 | M11: =+M10 -> 207.19615
A12: 34274 | B12: N | C12: 128 | D12: =SOJA!D12 -> 0.998519 | E12: =SOJA!E12 -> 1.023634 | F12: =+(C12*(D12/E12))/(AVERAGE(C$109)*AVERAGE(D$109)/AVERAGE(E$109))*100 -> 113.7608 | G12: =+E12/AVERAGE(E$2:E$13) -> 1.023634 | H12: =+(C12*D12)/G12 -> 124.8595 | I12: =+I11 -> 0 | J12: =+F12*(1-I12)/(F$109*(1-I$109))*100 -> 113.7608 | K12: =+H12*(1-I12) -> 124.8595 | L12: =+L11 -> 134.93063 | M12: =+M11 -> 207.19615
A13: 34304 | B13: D-93 | C13: 123 | D13: =SOJA!D13 -> 0.9985952 | E13: =SOJA!E13 -> 1.0234997 | F13: =+(C13*(D13/E13))/(AVERAGE(C$109)*AVERAGE(D$109)/AVERAGE(E$109))*100 -> 109.33971 | G13: =+E13/AVERAGE(E$2:E$13) -> 1.0234997 | H13: =+(C13*D13)/G13 -> 120.00708 | I13: =+I12 -> 0 | J13: =+F13*(1-I13)/(F$109*(1-I$109))*100 -> 109.33971 | K13: =+H13*(1-I13) -> 120.00708 | L13: =+L12 -> 134.93063 | M13: =+M12 -> 207.19615
A14: 34335 | B14: E-94 | C14: 120 | D14: =SOJA!D14 -> 0.9985714 | E14: =SOJA!E14 -> 1.0245302 | F14: =+(C14*(D14/E14))/(AVERAGE(C$109)*AVERAGE(D$109)/AVERAGE(E$109))*100 -> 106.56306 | G14: =+E14/AVERAGE(E$2:E$13) -> 1.0245302 | H14: =+(C14*D14)/G14 -> 116.95953 | I14: =+I13 -> 0 | J14: =+F14*(1-I14)/(F$109*(1-I$109))*100 -> 106.56306 | K14: =+H14*(1-I14) -> 116.95953 | L14: =+L13 -> 134.93063 | M14: =+M13 -> 207.19615
... A111: 37288 | B111: F | C111: 116 | D111: =SOJA!D111 -> 2.128 | E111: =SOJA!E111 -> 1.1049591 | F111: =+(C111*(D111/E111))/(AVERAGE(C$109)*AVERAGE(D$109)/AVERAGE(E$109))*100 -> 203.54219 | G111: =+E111/AVERAGE(E$2:E$13) -> 1.1049591 | H111: =+(C111*D111)/G111 -> 223.40012 | I111: =+I110 -> 0 | J111: =+F111*(1-I111)/(F$109*(1-I$109))*100 -> 203.54219 | K111: =+H111*(1-I111) -> 223.40012 | L111: =+L110 -> 134.93063 | M111: =+M110 -> 207.19615
A112: 37316 | B112: M | C112: 115 | D112: =SOJA!D112 -> 2.5452632 | E112: =SOJA!E112 -> 1.1487411 | F112: =+(C112*(D112/E112))/(AVERAGE(C$109)*AVERAGE(D$109)/AVERAGE(E$109))*100 -> 232.15572 | G112: =+E112/AVERAGE(E$2:E$13) -> 1.1487411 | H112: =+(C112*D112)/G112 -> 254.80524 | I112: 0 | J112: =+F112*(1-I112)/(F$109*(1-I$109))*100 -> 232.15572 | K112: =+H112*(1-I112) -> 254.80524 | L112: =+L111 -> 134.93063 | M112: =+M111 -> 207.19615
A113: 37347 | B113: A | C113: 124 | D113: =SOJA!D113 -> 3.0331818 | E113: =SOJA!E113 -> 1.2680686 | F113: =+(C113*(D113/E113))/(AVERAGE(C$109)*AVERAGE(D$109)/AVERAGE(E$109))*100 -> 270.23925 | G113: =+E113/AVERAGE(E$2:E$13) -> 1.2680686 | H113: =+(C113*D113)/G113 -> 296.60426 | I113: 0.2 | J113: =+F113*(1-I113)/(F$109*(1-I$109))*100 -> 216.1914 | K113: =+H113*(1-I113) -> 237.28341 | L113: =+L112 -> 134.93063 | M113: =+M112 -> 207.19615
A114: 37377 | B114: M | C114: 136 | D114: =SOJA!D114 -> 3.4422727 | E114: =SOJA!E114 -> 1.318933 | F114: =+(C114*(D114/E114))/(AVERAGE(C$109)*AVERAGE(D$109)/AVERAGE(E$109))*100 -> 323.39441 | G114: =+E114/AVERAGE(E$2:E$13) -> 1.318933 | H114: =+(C114*D114)/G114 -> 354.94533 | I114: =+I113 -> 0.2 | J114: =+F114*(1-I114)/(F$109*(1-I$109))*100 -> 258.71552 | K114: =+H114*(1-I114) -> 283.95626 | L114: =+L113 -> 134.93063 | M114: =+M113 -> 207.19615
A115: 37408 | B115: J | C115: 152 | D115: =SOJA!D115 -> 3.7165 | E115: =SOJA!E115 -> 1.3666854 | F115: =+(C115*(D115/E115))/(AVERAGE(C$109)*AVERAGE(D$109)/AVERAGE(E$109))*100 -> 376.59991 | G115: =+E115/AVERAGE(E$2:E$13) -> 1.3666854 | H115: =+(C115*D115)/G115 -> 413.34165 | I115: =+I114 -> 0.2 | J115: =+F115*(1-I115)/(F$109*(1-I$109))*100 -> 301.27993 | K115: =+H115*(1-I115) -> 330.67332 | L115: =+L114 -> 134.93063 | M115: =+M114 -> 207.19615
A116: 37438 | B116: J | C116: 169 | D116: =SOJA!D116 -> 3.6730435 | E116: =SOJA!E116 -> 1.4102528 | F116: =+(C116*(D116/E116))/(AVERAGE(C$109)*AVERAGE(D$109)/AVERAGE(E$109))*100 -> 401.03922 | G116: =+E116/AVERAGE(E$2:E$13) -> 1.4102528 | H116: =+(C116*D116)/G116 -> 440.1653 | I116: =+I115 -> 0.2 | J116: =+F116*(1-I116)/(F$109*(1-I$109))*100 -> 320.83138 | K116: =+H116*(1-I116) -> 352.13224 | L116: =+L115 -> 134.93063 | M116: =+M115 -> 207.19615
A117: 37469 | B117: A | C117: 180 | D117: =SOJA!D117 -> 3.6519048 | E117: =SOJA!E117 -> 1.4433039 | F117: =+(C117*(D117/E117))/(AVERAGE(C$109)*AVERAGE(D$109)/AVERAGE(E$109))*100 -> 414.95901 | G117: =+E117/AVERAGE(E$2:E$13) -> 1.4433039 | H117: =+(C117*D117)/G117 -> 455.44313 | I117: =+I116 -> 0.2 | J117: =+F117*(1-I117)/(F$109*(1-I$109))*100 -> 331.96721 | K117: =+H117*(1-I117) -> 364.35451 | L117: =+L116 -> 134.93063 | M117: =+M116 -> 207.19615
A118: 37500 | B118: S | C118: 196 | D118: =SOJA!D118 -> 3.677619 | E118: =SOJA!E118 -> 1.4627268 | F118: =+(C118*(D118/E118))/(AVERAGE(C$109)*AVERAGE(D$109)/AVERAGE(E$109))*100 -> 448.98376 | G118: =+E118/AVERAGE(E$2:E$13) -> 1.4627268 | H118: =+(C118*D118)/G118 -> 492.78739 | I118: =+I117 -> 0.2 | J118: =+F118*(1-I118)/(F$109*(1-I$109))*100 -> 359.18701 | K118: =+H118*(1-I118) -> 394.22991 | L118: =+L117 -> 134.93063 | M118: =+M117 -> 207.19615
A119: 37530 | B119: O | C119: 184 | D119: =SOJA!D119 -> 3.683913 | E119: =SOJA!E119 -> 1.4659461 | F119: =+(C119*(D119/E119))/(AVERAGE(C$109)*AVERAGE(D$109)/AVERAGE(E$109))*100 -> 421.28912 | G119: =+E119/AVERAGE(E$2:E$13) -> 1.4659461 | H119: =+(C119*D119)/G119 -> 462.39081 | I119: =+I118 -> 0.2 | J119: =+F119*(1-I119)/(F$109*(1-I$109))*100 -> 337.03129 | K119: =+H119*(1-I119) -> 369.91265 | L119: =+L118 -> 134.93063 | M119: =+M118 -> 207.19615
A120: 37561 | B120: N | C120: 141 | D120: =SOJA!D120 -> 3.5647619 | E120: =SOJA!E120 -> 1.4734577 | F120: =+(C120*(D120/E120))/(AVERAGE(C$109)*AVERAGE(D$109)/AVERAGE(E$109))*100 -> 310.80143 | G120: =+E120/AVERAGE(E$2:E$13) -> 1.4734577 | H120: =+(C120*D120)/G120 -> 341.12376 | I120: =+I119 -> 0.2 | J120: =+F120*(1-I120)/(F$109*(1-I$109))*100 -> 248.64115 | K120: =+H120*(1-I120) -> 272.89901 | L120: =+L119 -> 134.93063 | M120: =+M119 -> 207.19615
A121: 37591 | B121: D-02 | C121: 130 | D121: =SOJA!D121 -> 3.5261905 | E121: =SOJA!E121 -> 1.4762477 | F121: =+(C121*(D121/E121))/(AVERAGE(C$109)*AVERAGE(D$109)/AVERAGE(E$109))*100 -> 282.91822 | G121: =+E121/AVERAGE(E$2:E$13) -> 1.4762477 | H121: =+(C121*D121)/G121 -> 310.52022 | I121: =+I120 -> 0.2 | J121: =+F121*(1-I121)/(F$109*(1-I$109))*100 -> 226.33458 | K121: =+H121*(1-I121) -> 248.41617 | L121: =+L120 -> 134.93063 | M121: =+M120 -> 207.19615
A122: 37622 | B122: E-03 | C122: 142 | D122: =SOJA!D122 -> 3.2840909 | E122: =SOJA!E122 -> 1.4956706 | F122: =+(C122*(D122/E122))/(AVERAGE(C$109)*AVERAGE(D$109)/AVERAGE(E$109))*100 -> 284.07865 | G122: =+E122/AVERAGE(E$2:E$13) -> 1.4956706 | H122: =+(C122*D122)/G122 -> 311.79385 | I122: =+I121 -> 0.2 | J122: =+F122*(1-I122)/(F$109*(1-I$109))*100 -> 227.26292 | K122: =+H122*(1-I122) -> 249.43508 | L122: =+L121 -> 134.93063 | M122: =+M121 -> 207.19615
A123: 37653 | B123: F | C123: 147 | D123: =SOJA!D123 -> 3.1925 | E123: =SOJA!E123 -> 1.504148 | F123: =+(C123*(D123/E123))/(AVERAGE(C$109)*AVERAGE(D$109)/AVERAGE(E$109))*100 -> 284.26848 | G123: =+E123/AVERAGE(E$2:E$13) -> 1.504148 | H123: =+(C123*D123)/G123 -> 312.0022 | I123: =+I122 -> 0.2 | J123: =+F123*(1-I123)/(F$109*(1-I$109))*100 -> 227.41478 | K123: =+H123*(1-I123) -> 249.60176 | L123: =+L122 -> 134.93063 | M123: =+M122 -> 207.19615
A124: 37681 | B124: M | C124: 151 | D124: =SOJA!D124 -> 3.097619 | E124: =SOJA!E124 -> 1.5129474 | F124: =+(C124*(D124/E124))/(AVERAGE(C$109)*AVERAGE(D$109)/AVERAGE(E$109))*100 -> 281.67751 | G124: =+E124/AVERAGE(E$2:E$13) -> 1.5129474 | H124: =+(C124*D124)/G124 -> 309.15846 | I124: =+I123 -> 0.2 | J124: =+F124*(1-I124)/(F$109*(1-I$109))*100 -> 225.34201 | K124: =+H124*(1-I124) -> 247.32677 | L124: =+L123 -> 134.93063 | M124: =+M123 -> 207.19615
A125: 37712 | B125: A | C125: 150 | D125: =SOJA!D125 -> 2.9180952 | E125: =SOJA!E125 -> 1.5138058 | F125: =+(C125*(D125/E125))/(AVERAGE(C$109)*AVERAGE(D$109)/AVERAGE(E$109))*100 -> 263.44599 | G125: =+E125/AVERAGE(E$2:E$13) -> 1.5138058 | H125: =+(C125*D125)/G125 -> 289.14824 | I125: =+I124 -> 0.2 | J125: =+F125*(1-I125)/(F$109*(1-I$109))*100 -> 210.75679 | K125: =+H125*(1-I125) -> 231.31859 | L125: =+L124 -> 134.93063 | M125: =+M124 -> 207.19615
... A179: 39356 | B179: O | C179: 274 | D179: =SOJA!D179 -> 3.1804348 | E179: =SOJA!E179 -> 2.2659172 | F179: =+(C179*(D179/E179))/(AVERAGE(C$109)*AVERAGE(D$109)/AVERAGE(E$109))*100 -> 350.39998 | G179: =+E179/AVERAGE(E$2:E$13) -> 2.2659172 | H179: =+(C179*D179)/G179 -> 384.58561 | I179: =+I178 -> 0.2 | J179: =+F179*(1-I179)/(F$109*(1-I$109))*100 -> 280.31998 | K179: =+H179*(1-I179) -> 307.66849 | L179: =+L178 -> 134.93063 | M179: =+M178 -> 207.19615
A180: 39387 | B180: N | C180: 293 | D180: =SOJA!D180 -> 3.1514773 | E180: =SOJA!E180 -> 2.3177439 | F180: =+(C180*(D180/E180))/(AVERAGE(C$109)*AVERAGE(D$109)/AVERAGE(E$109))*100 -> 362.98392 | G180: =+E180/AVERAGE(E$2:E$13) -> 2.3177439 | H180: =+(C180*D180)/G180 -> 398.39727 | I180: 0.28 | J180: =+F180*(1-I180)/(F$109*(1-I$109))*100 -> 261.34843 | K180: =+H180*(1-I180) -> 286.84603 | L180: =+L179 -> 134.93063 | M180: =+M179 -> 207.19615
A181: 39417 | B181: D-07 | C181: 296 | D181: =SOJA!D181 -> 3.1575 | E181: =SOJA!E181 -> 2.3923771 | F181: =+(C181*(D181/E181))/(AVERAGE(C$109)*AVERAGE(D$109)/AVERAGE(E$109))*100 -> 355.93974 | G181: =+E181/AVERAGE(E$2:E$13) -> 2.3923771 | H181: =+(C181*D181)/G181 -> 390.66583 | I181: =+I180 -> 0.28 | J181: =+F181*(1-I181)/(F$109*(1-I$109))*100 -> 256.27661 | K181: =+H181*(1-I181) -> 281.2794 | L181: =+L180 -> 134.93063 | M181: =+M180 -> 207.19615
A182: 39448 | B182: E-08 | C182: 314 | D182: =SOJA!D182 -> 3.1640476 | E182: =SOJA!E182 -> 2.4469229 | F182: =+(C182*(D182/E182))/(AVERAGE(C$109)*AVERAGE(D$109)/AVERAGE(E$109))*100 -> 369.93329 | G182: =+E182/AVERAGE(E$2:E$13) -> 2.4469229 | H182: =+(C182*D182)/G182 -> 406.02463 | I182: =+I181 -> 0.28 | J182: =+F182*(1-I182)/(F$109*(1-I$109))*100 -> 266.35197 | K182: =+H182*(1-I182) -> 292.33773 | L182: =+L181 -> 134.93063 | M182: =+M181 -> 207.19615
A183: 39479 | B183: F | C183: 345 | D183: =SOJA!D183 -> 3.1728571 | E183: =SOJA!E183 -> 2.4730875 | F183: =+(C183*(D183/E183))/(AVERAGE(C$109)*AVERAGE(D$109)/AVERAGE(E$109))*100 -> 403.27487 | G183: =+E183/AVERAGE(E$2:E$13) -> 2.4730875 | H183: =+(C183*D183)/G183 -> 442.61907 | I183: =+I182 -> 0.28 | J183: =+F183*(1-I183)/(F$109*(1-I$109))*100 -> 290.35791 | K183: =+H183*(1-I183) -> 318.68573 | L183: =+L182 -> 134.93063 | M183: =+M182 -> 207.19615
A184: 39508 | B184: M | C184: 347 | D184: =SOJA!D184 -> 3.1726667 | E184: =SOJA!E184 -> 2.5477943 | F184: =+(C184*(D184/E184))/(AVERAGE(C$109)*AVERAGE(D$109)/AVERAGE(E$109))*100 -> 393.69563 | G184: =+E184/AVERAGE(E$2:E$13) -> 2.5477943 | H184: =+(C184*D184)/G184 -> 432.10526 | I184: =+I183 -> 0.28 | J184: =+F184*(1-I184)/(F$109*(1-I$109))*100 -> 283.46085 | K184: =+H184*(1-I184) -> 311.11579 | L184: =+L183 -> 134.93063 | M184: =+M183 -> 207.19615
A185: 39539 | B185: A | C185: 372 | D185: =SOJA!D185 -> 3.1868182 | E185: =SOJA!E185 -> 2.6050694 | F185: =+(C185*(D185/E185))/(AVERAGE(C$109)*AVERAGE(D$109)/AVERAGE(E$109))*100 -> 414.62164 | G185: =+E185/AVERAGE(E$2:E$13) -> 2.6050694 | H185: =+(C185*D185)/G185 -> 455.07285 | I185: =+I184 -> 0.28 | J185: =+F185*(1-I185)/(F$109*(1-I$109))*100 -> 298.52758 | K185: =+H185*(1-I185) -> 327.65245 | L185: =+L184 -> 134.93063 | M185: =+M184 -> 207.19615
A186: 39569 | B186: M | C186: 353 | D186: =SOJA!D186 -> 3.183 | E186: =SOJA!E186 -> 2.661464 | F186: =+(C186*(D186/E186))/(AVERAGE(C$109)*AVERAGE(D$109)/AVERAGE(E$109))*100 -> 384.6465 | G186: =+E186/AVERAGE(E$2:E$13) -> 2.661464 | H186: =+(C186*D186)/G186 -> 422.17328 | I186: =+I185 -> 0.28 | J186: =+F186*(1-I186)/(F$109*(1-I$109))*100 -> 276.94548 | K186: =+H186*(1-I186) -> 303.96476 | L186: =+L185 -> 134.93063 | M186: =+M185 -> 207.19615
A187: 39600 | B187: J | C187: 356 | D187: =SOJA!D187 -> 3.0738095 | E187: =SOJA!E187 -> 2.6904331 | F187: =+(C187*(D187/E187))/(AVERAGE(C$109)*AVERAGE(D$109)/AVERAGE(E$109))*100 -> 370.57472 | G187: =+E187/AVERAGE(E$2:E$13) -> 2.6904331 | H187: =+(C187*D187)/G187 -> 406.72864 | I187: =+I186 -> 0.28 | J187: =+F187*(1-I187)/(F$109*(1-I$109))*100 -> 266.8138 | K187: =+H187*(1-I187) -> 292.84462 | L187: =+L186 -> 134.93063 | M187: =+M186 -> 207.19615
A188: 39630 | B188: J | C188: 331 | D188: =SOJA!D188 -> 3.0465217 | E188: =SOJA!E188 -> 2.7219237 | F188: =+(C188*(D188/E188))/(AVERAGE(C$109)*AVERAGE(D$109)/AVERAGE(E$109))*100 -> 337.54165 | G188: =+E188/AVERAGE(E$2:E$13) -> 2.7219237 | H188: =+(C188*D188)/G188 -> 370.4728 | I188: =+I187 -> 0.28 | J188: =+F188*(1-I188)/(F$109*(1-I$109))*100 -> 243.02999 | K188: =+H188*(1-I188) -> 266.74042 | L188: =+L187 -> 134.93063 | M188: =+M187 -> 207.19615
A189: 39661 | B189: A | C189: 304 | D189: =SOJA!D189 -> 3.0538095 | E189: =SOJA!E189 -> 2.7654872 | F189: =+(C189*(D189/E189))/(AVERAGE(C$109)*AVERAGE(D$109)/AVERAGE(E$109))*100 -> 305.85453 | G189: =+E189/AVERAGE(E$2:E$13) -> 2.7654872 | H189: =+(C189*D189)/G189 -> 335.69423 | I189: =+I188 -> 0.28 | J189: =+F189*(1-I189)/(F$109*(1-I$109))*100 -> 220.21526 | K189: =+H189*(1-I189) -> 241.69984 | L189: =+L188 -> 134.93063 | M189: =+M188 -> 207.19615
...

Sheet MAIZ
C1: FOB USD/Ton | D1: com3500 $/USD | E1: IPC 1993=1 | F1: INDICE FOB*FX/IPC todo base 1993 (1) | G1: FX 1993=1 | H1: Precio FOB*FX/(IPC 1993=1) = FOB REAL | I1: DEX | J1: (1)*(1-DEX) | K1: FOB REAL*(1-DEX) = PRP
A2: 33970 | B2: E-93 | C2: 118 | D2: =SOJA!D2 -> 0.99874 | E2: =SOJA!E2 -> 0.96122511 | F2: =+(C2*(D2/E2))/(AVERAGE(C$109)*AVERAGE(D$109)/AVERAGE(E$109))*100 -> 124.24554 | G2: =+E2/AVERAGE(E$2:E$13) -> 0.96122511 | H2: =+(C2*D2)/G2 -> 122.60533 | I2: 0 | J2: =+F2*(1-I2)/(F$109*(1-I$109))*100 -> 124.24554 | K2: =+H2*(1-I2) -> 122.60533 | L2: =+AVERAGE(K2:K109) -> 104.72558 | M2: =+AVERAGE(K110:K277) -> 160.4379
A3: 34001 | B3: F | C3: 94 | D3: =SOJA!D3 -> 0.999155 | E3: =SOJA!E3 -> 0.96824627 | F3: =+(C3*(D3/E3))/(AVERAGE(C$109)*AVERAGE(D$109)/AVERAGE(E$109))*100 -> 98.298378 | G3: =+E3/AVERAGE(E$2:E$13) -> 0.96824627 | H3: =+(C3*D3)/G3 -> 97.000704 | I3: =+I2 -> 0 | J3: =+F3*(1-I3)/(F$109*(1-I$109))*100 -> 98.298378 | K3: =+H3*(1-I3) -> 97.000704 | L3: =+L2 -> 104.72558 | M3: =+M2 -> 160.4379
A4: 34029 | B4: M | C4: 84 | D4: =SOJA!D4 -> 0.999687 | E4: =SOJA!E4 -> 0.97552607 | F4: =+(C4*(D4/E4))/(AVERAGE(C$109)*AVERAGE(D$109)/AVERAGE(E$109))*100 -> 87.232017 | G4: =+E4/AVERAGE(E$2:E$13) -> 0.97552607 | H4: =+(C4*D4)/G4 -> 86.080435 | I4: =+I3 -> 0 | J4: =+F4*(1-I4)/(F$109*(1-I$109))*100 -> 87.232017 | K4: =+H4*(1-I4) -> 86.080435 | L4: =+L3 -> 104.72558 | M4: =+M3 -> 160.4379
A5: 34060 | B5: A | C5: 91 | D5: =SOJA!D5 -> 0.99916 | E5: =SOJA!E5 -> 0.98572347 | F5: =+(C5*(D5/E5))/(AVERAGE(C$109)*AVERAGE(D$109)/AVERAGE(E$109))*100 -> 93.474424 | G5: =+E5/AVERAGE(E$2:E$13) -> 0.98572347 | H5: =+(C5*D5)/G5 -> 92.240433 | I5: =+I4 -> 0 | J5: =+F5*(1-I5)/(F$109*(1-I$109))*100 -> 93.474424 | K5: =+H5*(1-I5) -> 92.240433 | L5: =+L4 -> 104.72558 | M5: =+M4 -> 160.4379
A6: 34090 | B6: M | C6: 96 | D6: =SOJA!D6 -> 0.999395 | E6: =SOJA!E6 -> 0.99840532 | F6: =+(C6*(D6/E6))/(AVERAGE(C$109)*AVERAGE(D$109)/AVERAGE(E$109))*100 -> 97.380721 | G6: =+E6/AVERAGE(E$2:E$13) -> 0.99840532 | H6: =+(C6*D6)/G6 -> 96.095161 | I6: =+I5 -> 0 | J6: =+F6*(1-I6)/(F$109*(1-I$109))*100 -> 97.380721 | K6: =+H6*(1-I6) -> 96.095161 | L6: =+L5 -> 104.72558 | M6: =+M5 -> 160.4379
A7: 34121 | B7: J | C7: 97 | D7: =SOJA!D7 -> 0.9992857 | E7: =SOJA!E7 -> 1.005587 | F7: =+(C7*(D7/E7))/(AVERAGE(C$109)*AVERAGE(D$109)/AVERAGE(E$109))*100 -> 97.681707 | G7: =+E7/AVERAGE(E$2:E$13) -> 1.005587 | H7: =+(C7*D7)/G7 -> 96.392174 | I7: =+I6 -> 0 | J7: =+F7*(1-I7)/(F$109*(1-I$109))*100 -> 97.681707 | K7: =+H7*(1-I7) -> 96.392174 | L7: =+L6 -> 104.72558 | M7: =+M6 -> 160.4379
A8: 34151 | B8: J | C8: 107 | D8: =SOJA!D8 -> 0.9989238 | E8: =SOJA!E8 -> 1.0088218 | F8: =+(C8*(D8/E8))/(AVERAGE(C$109)*AVERAGE(D$109)/AVERAGE(E$109))*100 -> 107.36757 | G8: =+E8/AVERAGE(E$2:E$13) -> 1.0088218 | H8: =+(C8*D8)/G8 -> 105.95017 | I8: =+I7 -> 0 | J8: =+F8*(1-I8)/(F$109*(1-I$109))*100 -> 107.36757 | K8: =+H8*(1-I8) -> 105.95017 | L8: =+L7 -> 104.72558 | M8: =+M7 -> 160.4379
A9: 34182 | B9: A | C9: 123 | D9: =SOJA!D9 -> 1.000175 | E9: =SOJA!E9 -> 1.0089836 | F9: =+(C9*(D9/E9))/(AVERAGE(C$109)*AVERAGE(D$109)/AVERAGE(E$109))*100 -> 123.55731 | G9: =+E9/AVERAGE(E$2:E$13) -> 1.0089836 | H9: =+(C9*D9)/G9 -> 121.92619 | I9: =+I8 -> 0 | J9: =+F9*(1-I9)/(F$109*(1-I$109))*100 -> 123.55731 | K9: =+H9*(1-I9) -> 121.92619 | L9: =+L8 -> 104.72558 | M9: =+M8 -> 160.4379
A10: 34213 | B10: S | C10: 124 | D10: =SOJA!D10 -> 1.0010095 | E10: =SOJA!E10 -> 1.0172986 | F10: =+(C10*(D10/E10))/(AVERAGE(C$109)*AVERAGE(D$109)/AVERAGE(E$109))*100 -> 123.6468 | G10: =+E10/AVERAGE(E$2:E$13) -> 1.0172986 | H10: =+(C10*D10)/G10 -> 122.0145 | I10: =+I9 -> 0 | J10: =+F10*(1-I10)/(F$109*(1-I$109))*100 -> 123.6468 | K10: =+H10*(1-I10) -> 122.0145 | L10: =+L9 -> 104.72558 | M10: =+M9 -> 160.4379
A11: 34243 | B11: O | C11: 130 | D11: =SOJA!D11 -> 0.999515 | E11: =SOJA!E11 -> 1.0230491 | F11: =+(C11*(D11/E11))/(AVERAGE(C$109)*AVERAGE(D$109)/AVERAGE(E$109))*100 -> 128.70863 | G11: =+E11/AVERAGE(E$2:E$13) -> 1.0230491 | H11: =+(C11*D11)/G11 -> 127.0095 | I11: =+I10 -> 0 | J11: =+F11*(1-I11)/(F$109*(1-I$109))*100 -> 128.70863 | K11: =+H11*(1-I11) -> 127.0095 | L11: =+L10 -> 104.72558 | M11: =+M10 -> 160.4379
A12: 34274 | B12: N | C12: 134 | D12: =SOJA!D12 -> 0.998519 | E12: =SOJA!E12 -> 1.023634 | F12: =+(C12*(D12/E12))/(AVERAGE(C$109)*AVERAGE(D$109)/AVERAGE(E$109))*100 -> 132.46096 | G12: =+E12/AVERAGE(E$2:E$13) -> 1.023634 | H12: =+(C12*D12)/G12 -> 130.71229 | I12: =+I11 -> 0 | J12: =+F12*(1-I12)/(F$109*(1-I$109))*100 -> 132.46096 | K12: =+H12*(1-I12) -> 130.71229 | L12: =+L11 -> 104.72558 | M12: =+M11 -> 160.4379
A13: 34304 | B13: D-93 | C13: 136 | D13: =SOJA!D13 -> 0.9985952 | E13: =SOJA!E13 -> 1.0234997 | F13: =+(C13*(D13/E13))/(AVERAGE(C$109)*AVERAGE(D$109)/AVERAGE(E$109))*100 -> 134.46589 | G13: =+E13/AVERAGE(E$2:E$13) -> 1.0234997 | H13: =+(C13*D13)/G13 -> 132.69076 | I13: =+I12 -> 0 | J13: =+F13*(1-I13)/(F$109*(1-I$109))*100 -> 134.46589 | K13: =+H13*(1-I13) -> 132.69076 | L13: =+L12 -> 104.72558 | M13: =+M12 -> 160.4379
A14: 34335 | B14: E-94 | C14: 127 | D14: =SOJA!D14 -> 0.9985714 | E14: =SOJA!E14 -> 1.0245302 | F14: =+(C14*(D14/E14))/(AVERAGE(C$109)*AVERAGE(D$109)/AVERAGE(E$109))*100 -> 125.43813 | G14: =+E14/AVERAGE(E$2:E$13) -> 1.0245302 | H14: =+(C14*D14)/G14 -> 123.78217 | I14: =+I13 -> 0 | J14: =+F14*(1-I14)/(F$109*(1-I$109))*100 -> 125.43813 | K14: =+H14*(1-I14) -> 123.78217 | L14: =+L13 -> 104.72558 | M14: =+M13 -> 160.4379
... A111: 37288 | B111: F | C111: 96 | D111: =SOJA!D111 -> 2.128 | E111: =SOJA!E111 -> 1.1049591 | F111: =+(C111*(D111/E111))/(AVERAGE(C$109)*AVERAGE(D$109)/AVERAGE(E$109))*100 -> 187.35621 | G111: =+E111/AVERAGE(E$2:E$13) -> 1.1049591 | H111: =+(C111*D111)/G111 -> 184.88286 | I111: =+I110 -> 0 | J111: =+F111*(1-I111)/(F$109*(1-I$109))*100 -> 187.35621 | K111: =+H111*(1-I111) -> 184.88286 | L111: =+L110 -> 104.72558 | M111: =+M110 -> 160.4379
A112: 37316 | B112: M | C112: 86 | D112: =SOJA!D112 -> 2.5452632 | E112: =SOJA!E112 -> 1.1487411 | F112: =+(C112*(D112/E112))/(AVERAGE(C$109)*AVERAGE(D$109)/AVERAGE(E$109))*100 -> 193.09918 | G112: =+E112/AVERAGE(E$2:E$13) -> 1.1487411 | H112: =+(C112*D112)/G112 -> 190.55001 | I112: 0 | J112: =+F112*(1-I112)/(F$109*(1-I$109))*100 -> 193.09918 | K112: =+H112*(1-I112) -> 190.55001 | L112: =+L111 -> 104.72558 | M112: =+M111 -> 160.4379
A113: 37347 | B113: A | C113: 87 | D113: =SOJA!D113 -> 3.0331818 | E113: =SOJA!E113 -> 1.2680686 | F113: =+(C113*(D113/E113))/(AVERAGE(C$109)*AVERAGE(D$109)/AVERAGE(E$109))*100 -> 210.88535 | G113: =+E113/AVERAGE(E$2:E$13) -> 1.2680686 | H113: =+(C113*D113)/G113 -> 208.10138 | I113: 0.2 | J113: =+F113*(1-I113)/(F$109*(1-I$109))*100 -> 168.70828 | K113: =+H113*(1-I113) -> 166.4811 | L113: =+L112 -> 104.72558 | M113: =+M112 -> 160.4379
A114: 37377 | B114: M | C114: 89 | D114: =SOJA!D114 -> 3.4422727 | E114: =SOJA!E114 -> 1.318933 | F114: =+(C114*(D114/E114))/(AVERAGE(C$109)*AVERAGE(D$109)/AVERAGE(E$109))*100 -> 235.38784 | G114: =+E114/AVERAGE(E$2:E$13) -> 1.318933 | H114: =+(C114*D114)/G114 -> 232.2804 | I114: =+I113 -> 0.2 | J114: =+F114*(1-I114)/(F$109*(1-I$109))*100 -> 188.31027 | K114: =+H114*(1-I114) -> 185.82432 | L114: =+L113 -> 104.72558 | M114: =+M113 -> 160.4379
A115: 37408 | B115: J | C115: 93 | D115: =SOJA!D115 -> 3.7165 | E115: =SOJA!E115 -> 1.3666854 | F115: =+(C115*(D115/E115))/(AVERAGE(C$109)*AVERAGE(D$109)/AVERAGE(E$109))*100 -> 256.28312 | G115: =+E115/AVERAGE(E$2:E$13) -> 1.3666854 | H115: =+(C115*D115)/G115 -> 252.89983 | I115: =+I114 -> 0.2 | J115: =+F115*(1-I115)/(F$109*(1-I$109))*100 -> 205.02649 | K115: =+H115*(1-I115) -> 202.31986 | L115: =+L114 -> 104.72558 | M115: =+M114 -> 160.4379
A116: 37438 | B116: J | C116: 98 | D116: =SOJA!D116 -> 3.6730435 | E116: =SOJA!E116 -> 1.4102528 | F116: =+(C116*(D116/E116))/(AVERAGE(C$109)*AVERAGE(D$109)/AVERAGE(E$109))*100 -> 258.65843 | G116: =+E116/AVERAGE(E$2:E$13) -> 1.4102528 | H116: =+(C116*D116)/G116 -> 255.24379 | I116: =+I115 -> 0.2 | J116: =+F116*(1-I116)/(F$109*(1-I$109))*100 -> 206.92675 | K116: =+H116*(1-I116) -> 204.19503 | L116: =+L115 -> 104.72558 | M116: =+M115 -> 160.4379
A117: 37469 | B117: A | C117: 105 | D117: =SOJA!D117 -> 3.6519048 | E117: =SOJA!E117 -> 1.4433039 | F117: =+(C117*(D117/E117))/(AVERAGE(C$109)*AVERAGE(D$109)/AVERAGE(E$109))*100 -> 269.22936 | G117: =+E117/AVERAGE(E$2:E$13) -> 1.4433039 | H117: =+(C117*D117)/G117 -> 265.67516 | I117: =+I116 -> 0.2 | J117: =+F117*(1-I117)/(F$109*(1-I$109))*100 -> 215.38349 | K117: =+H117*(1-I117) -> 212.54013 | L117: =+L116 -> 104.72558 | M117: =+M116 -> 160.4379
A118: 37500 | B118: S | C118: 108 | D118: =SOJA!D118 -> 3.677619 | E118: =SOJA!E118 -> 1.4627268 | F118: =+(C118*(D118/E118))/(AVERAGE(C$109)*AVERAGE(D$109)/AVERAGE(E$109))*100 -> 275.16851 | G118: =+E118/AVERAGE(E$2:E$13) -> 1.4627268 | H118: =+(C118*D118)/G118 -> 271.53591 | I118: =+I117 -> 0.2 | J118: =+F118*(1-I118)/(F$109*(1-I$109))*100 -> 220.13481 | K118: =+H118*(1-I118) -> 217.22873 | L118: =+L117 -> 104.72558 | M118: =+M117 -> 160.4379
A119: 37530 | B119: O | C119: 105 | D119: =SOJA!D119 -> 3.683913 | E119: =SOJA!E119 -> 1.4659461 | F119: =+(C119*(D119/E119))/(AVERAGE(C$109)*AVERAGE(D$109)/AVERAGE(E$109))*100 -> 267.3943 | G119: =+E119/AVERAGE(E$2:E$13) -> 1.4659461 | H119: =+(C119*D119)/G119 -> 263.86432 | I119: =+I118 -> 0.2 | J119: =+F119*(1-I119)/(F$109*(1-I$109))*100 -> 213.91544 | K119: =+H119*(1-I119) -> 211.09146 | L119: =+L118 -> 104.72558 | M119: =+M118 -> 160.4379
A120: 37561 | B120: N | C120: 107 | D120: =SOJA!D120 -> 3.5647619 | E120: =SOJA!E120 -> 1.4734577 | F120: =+(C120*(D120/E120))/(AVERAGE(C$109)*AVERAGE(D$109)/AVERAGE(E$109))*100 -> 262.33008 | G120: =+E120/AVERAGE(E$2:E$13) -> 1.4734577 | H120: =+(C120*D120)/G120 -> 258.86697 | I120: =+I119 -> 0.2 | J120: =+F120*(1-I120)/(F$109*(1-I$109))*100 -> 209.86407 | K120: =+H120*(1-I120) -> 207.09357 | L120: =+L119 -> 104.72558 | M120: =+M119 -> 160.4379
A121: 37591 | B121: D-02 | C121: 104 | D121: =SOJA!D121 -> 3.5261905 | E121: =SOJA!E121 -> 1.4762477 | F121: =+(C121*(D121/E121))/(AVERAGE(C$109)*AVERAGE(D$109)/AVERAGE(E$109))*100 -> 251.73948 | G121: =+E121/AVERAGE(E$2:E$13) -> 1.4762477 | H121: =+(C121*D121)/G121 -> 248.41617 | I121: =+I120 -> 0.2 | J121: =+F121*(1-I121)/(F$109*(1-I$109))*100 -> 201.39158 | K121: =+H121*(1-I121) -> 198.73294 | L121: =+L120 -> 104.72558 | M121: =+M120 -> 160.4379
A122: 37622 | B122: E-03 | C122: 101 | D122: =SOJA!D122 -> 3.2840909 | E122: =SOJA!E122 -> 1.4956706 | F122: =+(C122*(D122/E122))/(AVERAGE(C$109)*AVERAGE(D$109)/AVERAGE(E$109))*100 -> 224.73569 | G122: =+E122/AVERAGE(E$2:E$13) -> 1.4956706 | H122: =+(C122*D122)/G122 -> 221.76887 | I122: =+I121 -> 0.2 | J122: =+F122*(1-I122)/(F$109*(1-I$109))*100 -> 179.78855 | K122: =+H122*(1-I122) -> 177.41509 | L122: =+L121 -> 104.72558 | M122: =+M121 -> 160.4379
A123: 37653 | B123: F | C123: 100 | D123: =SOJA!D123 -> 3.1925 | E123: =SOJA!E123 -> 1.504148 | F123: =+(C123*(D123/E123))/(AVERAGE(C$109)*AVERAGE(D$109)/AVERAGE(E$109))*100 -> 215.08583 | G123: =+E123/AVERAGE(E$2:E$13) -> 1.504148 | H123: =+(C123*D123)/G123 -> 212.2464 | I123: =+I122 -> 0.2 | J123: =+F123*(1-I123)/(F$109*(1-I$109))*100 -> 172.06866 | K123: =+H123*(1-I123) -> 169.79712 | L123: =+L122 -> 104.72558 | M123: =+M122 -> 160.4379
A124: 37681 | B124: M | C124: 96 | D124: =SOJA!D124 -> 3.097619 | E124: =SOJA!E124 -> 1.5129474 | F124: =+(C124*(D124/E124))/(AVERAGE(C$109)*AVERAGE(D$109)/AVERAGE(E$109))*100 -> 199.18053 | G124: =+E124/AVERAGE(E$2:E$13) -> 1.5129474 | H124: =+(C124*D124)/G124 -> 196.55108 | I124: =+I123 -> 0.2 | J124: =+F124*(1-I124)/(F$109*(1-I$109))*100 -> 159.34443 | K124: =+H124*(1-I124) -> 157.24086 | L124: =+L123 -> 104.72558 | M124: =+M123 -> 160.4379
A125: 37712 | B125: A | C125: 98 | D125: =SOJA!D125 -> 2.9180952 | E125: =SOJA!E125 -> 1.5138058 | F125: =+(C125*(D125/E125))/(AVERAGE(C$109)*AVERAGE(D$109)/AVERAGE(E$109))*100 -> 191.43742 | G125: =+E125/AVERAGE(E$2:E$13) -> 1.5138058 | H125: =+(C125*D125)/G125 -> 188.91018 | I125: =+I124 -> 0.2 | J125: =+F125*(1-I125)/(F$109*(1-I$109))*100 -> 153.14994 | K125: =+H125*(1-I125) -> 151.12815 | L125: =+L124 -> 104.72558 | M125: =+M124 -> 160.4379
... A179: 39356 | B179: O | C179: 169 | D179: =SOJA!D179 -> 3.1804348 | E179: =SOJA!E179 -> 2.2659172 | F179: =+(C179*(D179/E179))/(AVERAGE(C$109)*AVERAGE(D$109)/AVERAGE(E$109))*100 -> 240.38127 | G179: =+E179/AVERAGE(E$2:E$13) -> 2.2659172 | H179: =+(C179*D179)/G179 -> 237.20791 | I179: =+I178 -> 0.2 | J179: =+F179*(1-I179)/(F$109*(1-I$109))*100 -> 192.30502 | K179: =+H179*(1-I179) -> 189.76633 | L179: =+L178 -> 104.72558 | M179: =+M178 -> 160.4379
A180: 39387 | B180: N | C180: 167 | D180: =SOJA!D180 -> 3.1514773 | E180: =SOJA!E180 -> 2.3177439 | F180: =+(C180*(D180/E180))/(AVERAGE(C$109)*AVERAGE(D$109)/AVERAGE(E$109))*100 -> 230.11062 | G180: =+E180/AVERAGE(E$2:E$13) -> 2.3177439 | H180: =+(C180*D180)/G180 -> 227.07284 | I180: 0.25 | J180: =+F180*(1-I180)/(F$109*(1-I$109))*100 -> 172.58297 | K180: =+H180*(1-I180) -> 170.30463 | L180: =+L179 -> 104.72558 | M180: =+M179 -> 160.4379
A181: 39417 | B181: D-07 | C181: 159 | D181: =SOJA!D181 -> 3.1575 | E181: =SOJA!E181 -> 2.3923771 | F181: =+(C181*(D181/E181))/(AVERAGE(C$109)*AVERAGE(D$109)/AVERAGE(E$109))*100 -> 212.65829 | G181: =+E181/AVERAGE(E$2:E$13) -> 2.3923771 | H181: =+(C181*D181)/G181 -> 209.8509 | I181: =+I180 -> 0.25 | J181: =+F181*(1-I181)/(F$109*(1-I$109))*100 -> 159.49371 | K181: =+H181*(1-I181) -> 157.38818 | L181: =+L180 -> 104.72558 | M181: =+M180 -> 160.4379
